{
    "title": "Getting funcap plugin work in IDA pro",
    "link": "https://reverseengineering.stackexchange.com/questions/5974/getting-funcap-plugin-work-in-ida-pro",
    "content": "<html><body><div class=\"s-prose js-post-body\" itemprop=\"text\">\n <p>\n  I am trying to use\n  <a href=\"https://github.com/deresz/funcap\" rel=\"nofollow\">\n   funcap plugin\n  </a>\n  in IDA pro 6.1. However, after loading the plugin (with\n  <kbd>\n   Alt\n  </kbd>\n  +\n  <kbd>\n   F7\n  </kbd>\n  ) and pressing the debugger's run button, it returns me:\n </p>\n <pre><code>Internal error 30191 \n</code></pre>\n <p>\n  Any idea what is the problem?\n </p>\n <p>\n  P.S.: I have tried with both Python 2.6 and 2.7.\n </p>\n</div>\n</body></html>",
    "votes": "3",
    "answers": 1,
    "views": "906",
    "tags": [
        "ida",
        "ida-plugin"
    ],
    "user": "user3403765",
    "time": "Jul 29, 2014 at 17:10",
    "comments": [],
    "answers_data": [
        {
            "content": "<html><body><div class=\"s-prose js-post-body\" itemprop=\"text\">\n <p>\n  By any chance do you have the IDAStealth plugin installed? If so, do you have SEH debugging support features enabled?\n </p>\n <p>\n  As per the bugfix for the plugin:\n </p>\n <pre><code>Bugfix: If any of the SEH debugging support features was used an \"internal error 30191\" would be raised in IDA as soon as the exception occurred in the debuggee\n</code></pre>\n <p>\n  <a href=\"http://newgre.net/idastealth\" rel=\"nofollow\">\n   http://newgre.net/idastealth\n  </a>\n </p>\n</div>\n</body></html>",
            "votes": "4",
            "user": "Fred Concklin",
            "time": "Jul 30, 2014 at 3:02",
            "is_accepted": false,
            "comments": [
                {
                    "user": "user3403765",
                    "text": "<span class=\"comment-copy\">Thanks for your reply. But, no. I don't.</span>",
                    "time": null
                }
            ]
        }
    ]
}